[2024-06-05T16:42:33.040+0000] {local_task_job_runner.py:120} INFO - ::group::Pre task execution logs
[2024-06-05T16:42:33.108+0000] {taskinstance.py:2076} INFO - Dependencies all met for dep_context=non-requeueable deps ti=<TaskInstance: s3_postgres.create_postgres_table manual__2024-06-05T16:35:59.651756+00:00 [queued]>
[2024-06-05T16:42:33.132+0000] {taskinstance.py:2076} INFO - Dependencies all met for dep_context=requeueable deps ti=<TaskInstance: s3_postgres.create_postgres_table manual__2024-06-05T16:35:59.651756+00:00 [queued]>
[2024-06-05T16:42:33.134+0000] {taskinstance.py:2306} INFO - Starting attempt 3 of 4
[2024-06-05T16:42:33.179+0000] {taskinstance.py:2330} INFO - Executing <Task(PythonOperator): create_postgres_table> on 2024-06-05 16:35:59.651756+00:00
[2024-06-05T16:42:33.200+0000] {warnings.py:110} WARNING - /home/***/.local/lib/python3.12/site-packages/***/task/task_runner/standard_task_runner.py:61: DeprecationWarning: This process (pid=177) is multi-threaded, use of fork() may lead to deadlocks in the child.
  pid = os.fork()

[2024-06-05T16:42:33.205+0000] {standard_task_runner.py:63} INFO - Started process 179 to run task
[2024-06-05T16:42:33.204+0000] {standard_task_runner.py:90} INFO - Running: ['***', 'tasks', 'run', 's3_postgres', 'create_postgres_table', 'manual__2024-06-05T16:35:59.651756+00:00', '--job-id', '712', '--raw', '--subdir', 'DAGS_FOLDER/pipe.py', '--cfg-path', '/tmp/tmpuxnd2rgr']
[2024-06-05T16:42:33.207+0000] {standard_task_runner.py:91} INFO - Job 712: Subtask create_postgres_table
[2024-06-05T16:42:33.329+0000] {task_command.py:426} INFO - Running <TaskInstance: s3_postgres.create_postgres_table manual__2024-06-05T16:35:59.651756+00:00 [running]> on host 3ca4815e3382
[2024-06-05T16:42:33.527+0000] {taskinstance.py:2648} INFO - Exporting env vars: AIRFLOW_CTX_DAG_OWNER='***' AIRFLOW_CTX_DAG_ID='s3_postgres' AIRFLOW_CTX_TASK_ID='create_postgres_table' AIRFLOW_CTX_EXECUTION_DATE='2024-06-05T16:35:59.651756+00:00' AIRFLOW_CTX_TRY_NUMBER='3' AIRFLOW_CTX_DAG_RUN_ID='manual__2024-06-05T16:35:59.651756+00:00'
[2024-06-05T16:42:33.530+0000] {taskinstance.py:430} INFO - ::endgroup::
[2024-06-05T16:42:33.545+0000] {base.py:84} INFO - Using connection ID 'postgres_default' for task execution.
[2024-06-05T16:42:33.569+0000] {taskinstance.py:441} INFO - ::group::Post task execution logs
[2024-06-05T16:42:33.572+0000] {taskinstance.py:2905} ERROR - Task failed with exception
Traceback (most recent call last):
  File "/home/airflow/.local/lib/python3.12/site-packages/airflow/models/taskinstance.py", line 465, in _execute_task
    result = _execute_callable(context=context, **execute_callable_kwargs)
             ^^^^^^^^^^^^^^^^^^^^^^^^^^^^^^^^^^^^^^^^^^^^^^^^^^^^^^^^^^^^^
  File "/home/airflow/.local/lib/python3.12/site-packages/airflow/models/taskinstance.py", line 432, in _execute_callable
    return execute_callable(context=context, **execute_callable_kwargs)
           ^^^^^^^^^^^^^^^^^^^^^^^^^^^^^^^^^^^^^^^^^^^^^^^^^^^^^^^^^^^^
  File "/home/airflow/.local/lib/python3.12/site-packages/airflow/models/baseoperator.py", line 400, in wrapper
    return func(self, *args, **kwargs)
           ^^^^^^^^^^^^^^^^^^^^^^^^^^^
  File "/home/airflow/.local/lib/python3.12/site-packages/airflow/operators/python.py", line 235, in execute
    return_value = self.execute_callable()
                   ^^^^^^^^^^^^^^^^^^^^^^^
  File "/home/airflow/.local/lib/python3.12/site-packages/airflow/operators/python.py", line 252, in execute_callable
    return self.python_callable(*self.op_args, **self.op_kwargs)
           ^^^^^^^^^^^^^^^^^^^^^^^^^^^^^^^^^^^^^^^^^^^^^^^^^^^^^
  File "/opt/airflow/dags/pipe.py", line 84, in create_table_postgres
    postgres_hook.run(create_table_query)
  File "/home/airflow/.local/lib/python3.12/site-packages/airflow/providers/common/sql/hooks/sql.py", line 411, in run
    with closing(self.get_conn()) as conn:
                 ^^^^^^^^^^^^^^^
  File "/home/airflow/.local/lib/python3.12/site-packages/airflow/providers/postgres/hooks/postgres.py", line 161, in get_conn
    self.conn = psycopg2.connect(**conn_args)
                ^^^^^^^^^^^^^^^^^^^^^^^^^^^^^
  File "/home/airflow/.local/lib/python3.12/site-packages/psycopg2/__init__.py", line 122, in connect
    conn = _connect(dsn, connection_factory=connection_factory, **kwasync)
           ^^^^^^^^^^^^^^^^^^^^^^^^^^^^^^^^^^^^^^^^^^^^^^^^^^^^^^^^^^^^^^^
psycopg2.OperationalError: connection to server at "host.docker.internal" (192.168.65.254), port 5432 failed: FATAL:  password authentication failed for user "***"

[2024-06-05T16:42:33.593+0000] {taskinstance.py:1206} INFO - Marking task as UP_FOR_RETRY. dag_id=s3_postgres, task_id=create_postgres_table, run_id=manual__2024-06-05T16:35:59.651756+00:00, execution_date=20240605T163559, start_date=20240605T164233, end_date=20240605T164233
[2024-06-05T16:42:33.617+0000] {standard_task_runner.py:110} ERROR - Failed to execute job 712 for task create_postgres_table (connection to server at "host.docker.internal" (192.168.65.254), port 5432 failed: FATAL:  password authentication failed for user "***"
; 179)
[2024-06-05T16:42:33.665+0000] {local_task_job_runner.py:240} INFO - Task exited with return code 1
[2024-06-05T16:42:33.707+0000] {taskinstance.py:3498} INFO - 0 downstream tasks scheduled from follow-on schedule check
[2024-06-05T16:42:33.710+0000] {local_task_job_runner.py:222} INFO - ::endgroup::
