[2024-06-08T14:24:47.233+0000] {local_task_job_runner.py:120} INFO - ::group::Pre task execution logs
[2024-06-08T14:24:47.257+0000] {taskinstance.py:2076} INFO - Dependencies all met for dep_context=non-requeueable deps ti=<TaskInstance: s3_postgres.download_and_insert_data scheduled__2024-06-07T00:00:00+00:00 [queued]>
[2024-06-08T14:24:47.266+0000] {taskinstance.py:2076} INFO - Dependencies all met for dep_context=requeueable deps ti=<TaskInstance: s3_postgres.download_and_insert_data scheduled__2024-06-07T00:00:00+00:00 [queued]>
[2024-06-08T14:24:47.267+0000] {taskinstance.py:2306} INFO - Starting attempt 2 of 2
[2024-06-08T14:24:47.283+0000] {taskinstance.py:2330} INFO - Executing <Task(PythonOperator): download_and_insert_data> on 2024-06-07 00:00:00+00:00
[2024-06-08T14:24:47.289+0000] {warnings.py:110} WARNING - /home/***/.local/lib/python3.12/site-packages/***/task/task_runner/standard_task_runner.py:61: DeprecationWarning: This process (pid=130) is multi-threaded, use of fork() may lead to deadlocks in the child.
  pid = os.fork()

[2024-06-08T14:24:47.291+0000] {standard_task_runner.py:63} INFO - Started process 132 to run task
[2024-06-08T14:24:47.292+0000] {standard_task_runner.py:90} INFO - Running: ['***', 'tasks', 'run', 's3_postgres', 'download_and_insert_data', 'scheduled__2024-06-07T00:00:00+00:00', '--job-id', '854', '--raw', '--subdir', 'DAGS_FOLDER/pipeline.py', '--cfg-path', '/tmp/tmpr0t09bs0']
[2024-06-08T14:24:47.293+0000] {standard_task_runner.py:91} INFO - Job 854: Subtask download_and_insert_data
[2024-06-08T14:24:47.342+0000] {task_command.py:426} INFO - Running <TaskInstance: s3_postgres.download_and_insert_data scheduled__2024-06-07T00:00:00+00:00 [running]> on host 728c6b2dbd3f
[2024-06-08T14:24:47.445+0000] {taskinstance.py:2648} INFO - Exporting env vars: AIRFLOW_CTX_DAG_OWNER='***' AIRFLOW_CTX_DAG_ID='s3_postgres' AIRFLOW_CTX_TASK_ID='download_and_insert_data' AIRFLOW_CTX_EXECUTION_DATE='2024-06-07T00:00:00+00:00' AIRFLOW_CTX_TRY_NUMBER='2' AIRFLOW_CTX_DAG_RUN_ID='scheduled__2024-06-07T00:00:00+00:00'
[2024-06-08T14:24:47.446+0000] {taskinstance.py:430} INFO - ::endgroup::
[2024-06-08T14:24:48.545+0000] {logging_mixin.py:188} INFO - Failed to find the bucket and corresponding files: An error occurred (InvalidAccessKeyId) when calling the ListBuckets operation: The AWS Access Key Id you provided does not exist in our records.
[2024-06-08T14:24:48.550+0000] {taskinstance.py:441} INFO - ::group::Post task execution logs
[2024-06-08T14:24:48.551+0000] {taskinstance.py:2905} ERROR - Task failed with exception
Traceback (most recent call last):
  File "/home/airflow/.local/lib/python3.12/site-packages/airflow/models/taskinstance.py", line 465, in _execute_task
    result = _execute_callable(context=context, **execute_callable_kwargs)
             ^^^^^^^^^^^^^^^^^^^^^^^^^^^^^^^^^^^^^^^^^^^^^^^^^^^^^^^^^^^^^
  File "/home/airflow/.local/lib/python3.12/site-packages/airflow/models/taskinstance.py", line 432, in _execute_callable
    return execute_callable(context=context, **execute_callable_kwargs)
           ^^^^^^^^^^^^^^^^^^^^^^^^^^^^^^^^^^^^^^^^^^^^^^^^^^^^^^^^^^^^
  File "/home/airflow/.local/lib/python3.12/site-packages/airflow/models/baseoperator.py", line 400, in wrapper
    return func(self, *args, **kwargs)
           ^^^^^^^^^^^^^^^^^^^^^^^^^^^
  File "/home/airflow/.local/lib/python3.12/site-packages/airflow/operators/python.py", line 235, in execute
    return_value = self.execute_callable()
                   ^^^^^^^^^^^^^^^^^^^^^^^
  File "/home/airflow/.local/lib/python3.12/site-packages/airflow/operators/python.py", line 252, in execute_callable
    return self.python_callable(*self.op_args, **self.op_kwargs)
           ^^^^^^^^^^^^^^^^^^^^^^^^^^^^^^^^^^^^^^^^^^^^^^^^^^^^^
  File "/opt/airflow/dags/pipeline.py", line 135, in download_and_insert_data
    insert_data_into_postgres(data)
  File "/opt/airflow/dags/pipeline.py", line 89, in insert_data_into_postgres
    df = pd.read_csv(file_path)
         ^^^^^^^^^^^^^^^^^^^^^^
  File "/home/airflow/.local/lib/python3.12/site-packages/pandas/io/parsers/readers.py", line 948, in read_csv
    return _read(filepath_or_buffer, kwds)
           ^^^^^^^^^^^^^^^^^^^^^^^^^^^^^^^
  File "/home/airflow/.local/lib/python3.12/site-packages/pandas/io/parsers/readers.py", line 611, in _read
    parser = TextFileReader(filepath_or_buffer, **kwds)
             ^^^^^^^^^^^^^^^^^^^^^^^^^^^^^^^^^^^^^^^^^^
  File "/home/airflow/.local/lib/python3.12/site-packages/pandas/io/parsers/readers.py", line 1448, in __init__
    self._engine = self._make_engine(f, self.engine)
                   ^^^^^^^^^^^^^^^^^^^^^^^^^^^^^^^^^
  File "/home/airflow/.local/lib/python3.12/site-packages/pandas/io/parsers/readers.py", line 1705, in _make_engine
    self.handles = get_handle(
                   ^^^^^^^^^^^
  File "/home/airflow/.local/lib/python3.12/site-packages/pandas/io/common.py", line 718, in get_handle
    ioargs = _get_filepath_or_buffer(
             ^^^^^^^^^^^^^^^^^^^^^^^^
  File "/home/airflow/.local/lib/python3.12/site-packages/pandas/io/common.py", line 460, in _get_filepath_or_buffer
    raise ValueError(msg)
ValueError: Invalid file path or buffer object type: <class 'NoneType'>
[2024-06-08T14:24:48.565+0000] {taskinstance.py:1206} INFO - Marking task as FAILED. dag_id=s3_postgres, task_id=download_and_insert_data, run_id=scheduled__2024-06-07T00:00:00+00:00, execution_date=20240607T000000, start_date=20240608T142447, end_date=20240608T142448
[2024-06-08T14:24:48.578+0000] {standard_task_runner.py:110} ERROR - Failed to execute job 854 for task download_and_insert_data (Invalid file path or buffer object type: <class 'NoneType'>; 132)
[2024-06-08T14:24:48.590+0000] {local_task_job_runner.py:240} INFO - Task exited with return code 1
[2024-06-08T14:24:48.617+0000] {taskinstance.py:3498} INFO - 0 downstream tasks scheduled from follow-on schedule check
[2024-06-08T14:24:48.621+0000] {local_task_job_runner.py:222} INFO - ::endgroup::
