[2024-06-05T16:47:37.553+0000] {local_task_job_runner.py:120} INFO - ::group::Pre task execution logs
[2024-06-05T16:47:37.573+0000] {taskinstance.py:2076} INFO - Dependencies all met for dep_context=non-requeueable deps ti=<TaskInstance: s3_postgres.fetch_recent_data manual__2024-06-05T16:35:59.651756+00:00 [queued]>
[2024-06-05T16:47:37.580+0000] {taskinstance.py:2076} INFO - Dependencies all met for dep_context=requeueable deps ti=<TaskInstance: s3_postgres.fetch_recent_data manual__2024-06-05T16:35:59.651756+00:00 [queued]>
[2024-06-05T16:47:37.581+0000] {taskinstance.py:2306} INFO - Starting attempt 1 of 2
[2024-06-05T16:47:37.594+0000] {taskinstance.py:2330} INFO - Executing <Task(PythonOperator): fetch_recent_data> on 2024-06-05 16:35:59.651756+00:00
[2024-06-05T16:47:37.600+0000] {warnings.py:110} WARNING - /home/***/.local/lib/python3.12/site-packages/***/task/task_runner/standard_task_runner.py:61: DeprecationWarning: This process (pid=95) is multi-threaded, use of fork() may lead to deadlocks in the child.
  pid = os.fork()

[2024-06-05T16:47:37.601+0000] {standard_task_runner.py:63} INFO - Started process 97 to run task
[2024-06-05T16:47:37.602+0000] {standard_task_runner.py:90} INFO - Running: ['***', 'tasks', 'run', 's3_postgres', 'fetch_recent_data', 'manual__2024-06-05T16:35:59.651756+00:00', '--job-id', '718', '--raw', '--subdir', 'DAGS_FOLDER/pipe.py', '--cfg-path', '/tmp/tmp9qaoiyzy']
[2024-06-05T16:47:37.603+0000] {standard_task_runner.py:91} INFO - Job 718: Subtask fetch_recent_data
[2024-06-05T16:47:37.649+0000] {task_command.py:426} INFO - Running <TaskInstance: s3_postgres.fetch_recent_data manual__2024-06-05T16:35:59.651756+00:00 [running]> on host 0c39f87f9155
[2024-06-05T16:47:37.729+0000] {taskinstance.py:2648} INFO - Exporting env vars: AIRFLOW_CTX_DAG_OWNER='***' AIRFLOW_CTX_DAG_ID='s3_postgres' AIRFLOW_CTX_TASK_ID='fetch_recent_data' AIRFLOW_CTX_EXECUTION_DATE='2024-06-05T16:35:59.651756+00:00' AIRFLOW_CTX_TRY_NUMBER='1' AIRFLOW_CTX_DAG_RUN_ID='manual__2024-06-05T16:35:59.651756+00:00'
[2024-06-05T16:47:37.730+0000] {taskinstance.py:430} INFO - ::endgroup::
[2024-06-05T16:47:37.739+0000] {base.py:84} INFO - Using connection ID 'postgres_default' for task execution.
[2024-06-05T16:47:37.763+0000] {taskinstance.py:441} INFO - ::group::Post task execution logs
[2024-06-05T16:47:37.764+0000] {taskinstance.py:2905} ERROR - Task failed with exception
Traceback (most recent call last):
  File "/home/airflow/.local/lib/python3.12/site-packages/airflow/models/taskinstance.py", line 465, in _execute_task
    result = _execute_callable(context=context, **execute_callable_kwargs)
             ^^^^^^^^^^^^^^^^^^^^^^^^^^^^^^^^^^^^^^^^^^^^^^^^^^^^^^^^^^^^^
  File "/home/airflow/.local/lib/python3.12/site-packages/airflow/models/taskinstance.py", line 432, in _execute_callable
    return execute_callable(context=context, **execute_callable_kwargs)
           ^^^^^^^^^^^^^^^^^^^^^^^^^^^^^^^^^^^^^^^^^^^^^^^^^^^^^^^^^^^^
  File "/home/airflow/.local/lib/python3.12/site-packages/airflow/models/baseoperator.py", line 400, in wrapper
    return func(self, *args, **kwargs)
           ^^^^^^^^^^^^^^^^^^^^^^^^^^^
  File "/home/airflow/.local/lib/python3.12/site-packages/airflow/operators/python.py", line 235, in execute
    return_value = self.execute_callable()
                   ^^^^^^^^^^^^^^^^^^^^^^^
  File "/home/airflow/.local/lib/python3.12/site-packages/airflow/operators/python.py", line 252, in execute_callable
    return self.python_callable(*self.op_args, **self.op_kwargs)
           ^^^^^^^^^^^^^^^^^^^^^^^^^^^^^^^^^^^^^^^^^^^^^^^^^^^^^
  File "/opt/airflow/dags/pipe.py", line 118, in fetch_recent_data_to_csv
    df.to_csv('/opt/airflow/data/recent_data.csv', index=False)
  File "/home/airflow/.local/lib/python3.12/site-packages/pandas/core/generic.py", line 3902, in to_csv
    return DataFrameRenderer(formatter).to_csv(
           ^^^^^^^^^^^^^^^^^^^^^^^^^^^^^^^^^^^^
  File "/home/airflow/.local/lib/python3.12/site-packages/pandas/io/formats/format.py", line 1152, in to_csv
    csv_formatter.save()
  File "/home/airflow/.local/lib/python3.12/site-packages/pandas/io/formats/csvs.py", line 247, in save
    with get_handle(
         ^^^^^^^^^^^
  File "/home/airflow/.local/lib/python3.12/site-packages/pandas/io/common.py", line 739, in get_handle
    check_parent_directory(str(handle))
  File "/home/airflow/.local/lib/python3.12/site-packages/pandas/io/common.py", line 604, in check_parent_directory
    raise OSError(rf"Cannot save file into a non-existent directory: '{parent}'")
OSError: Cannot save file into a non-existent directory: '/opt/***/data'
[2024-06-05T16:47:37.778+0000] {taskinstance.py:1206} INFO - Marking task as UP_FOR_RETRY. dag_id=s3_postgres, task_id=fetch_recent_data, run_id=manual__2024-06-05T16:35:59.651756+00:00, execution_date=20240605T163559, start_date=20240605T164737, end_date=20240605T164737
[2024-06-05T16:47:37.790+0000] {standard_task_runner.py:110} ERROR - Failed to execute job 718 for task fetch_recent_data (Cannot save file into a non-existent directory: '/opt/***/data'; 97)
[2024-06-05T16:47:37.815+0000] {local_task_job_runner.py:240} INFO - Task exited with return code 1
[2024-06-05T16:47:37.831+0000] {taskinstance.py:3498} INFO - 0 downstream tasks scheduled from follow-on schedule check
[2024-06-05T16:47:37.833+0000] {local_task_job_runner.py:222} INFO - ::endgroup::
