[2024-06-05T16:50:51.654+0000] {local_task_job_runner.py:120} INFO - ::group::Pre task execution logs
[2024-06-05T16:50:51.688+0000] {taskinstance.py:2076} INFO - Dependencies all met for dep_context=non-requeueable deps ti=<TaskInstance: s3_postgres.fetch_recent_data manual__2024-06-05T16:35:59.651756+00:00 [queued]>
[2024-06-05T16:50:51.699+0000] {taskinstance.py:2076} INFO - Dependencies all met for dep_context=requeueable deps ti=<TaskInstance: s3_postgres.fetch_recent_data manual__2024-06-05T16:35:59.651756+00:00 [queued]>
[2024-06-05T16:50:51.700+0000] {taskinstance.py:2306} INFO - Starting attempt 2 of 3
[2024-06-05T16:50:51.720+0000] {taskinstance.py:2330} INFO - Executing <Task(PythonOperator): fetch_recent_data> on 2024-06-05 16:35:59.651756+00:00
[2024-06-05T16:50:51.730+0000] {warnings.py:110} WARNING - /home/***/.local/lib/python3.12/site-packages/***/task/task_runner/standard_task_runner.py:61: DeprecationWarning: This process (pid=69) is multi-threaded, use of fork() may lead to deadlocks in the child.
  pid = os.fork()

[2024-06-05T16:50:51.732+0000] {standard_task_runner.py:63} INFO - Started process 73 to run task
[2024-06-05T16:50:51.732+0000] {standard_task_runner.py:90} INFO - Running: ['***', 'tasks', 'run', 's3_postgres', 'fetch_recent_data', 'manual__2024-06-05T16:35:59.651756+00:00', '--job-id', '724', '--raw', '--subdir', 'DAGS_FOLDER/pipe.py', '--cfg-path', '/tmp/tmp9qc_t3ee']
[2024-06-05T16:50:51.734+0000] {standard_task_runner.py:91} INFO - Job 724: Subtask fetch_recent_data
[2024-06-05T16:50:51.801+0000] {task_command.py:426} INFO - Running <TaskInstance: s3_postgres.fetch_recent_data manual__2024-06-05T16:35:59.651756+00:00 [running]> on host 6dbcf9923072
[2024-06-05T16:50:51.908+0000] {taskinstance.py:2648} INFO - Exporting env vars: AIRFLOW_CTX_DAG_OWNER='***' AIRFLOW_CTX_DAG_ID='s3_postgres' AIRFLOW_CTX_TASK_ID='fetch_recent_data' AIRFLOW_CTX_EXECUTION_DATE='2024-06-05T16:35:59.651756+00:00' AIRFLOW_CTX_TRY_NUMBER='2' AIRFLOW_CTX_DAG_RUN_ID='manual__2024-06-05T16:35:59.651756+00:00'
[2024-06-05T16:50:51.910+0000] {taskinstance.py:430} INFO - ::endgroup::
[2024-06-05T16:50:51.922+0000] {base.py:84} INFO - Using connection ID 'postgres_default' for task execution.
[2024-06-05T16:50:51.944+0000] {taskinstance.py:441} INFO - ::group::Post task execution logs
[2024-06-05T16:50:51.945+0000] {taskinstance.py:2905} ERROR - Task failed with exception
Traceback (most recent call last):
  File "/home/airflow/.local/lib/python3.12/site-packages/airflow/models/taskinstance.py", line 465, in _execute_task
    result = _execute_callable(context=context, **execute_callable_kwargs)
             ^^^^^^^^^^^^^^^^^^^^^^^^^^^^^^^^^^^^^^^^^^^^^^^^^^^^^^^^^^^^^
  File "/home/airflow/.local/lib/python3.12/site-packages/airflow/models/taskinstance.py", line 432, in _execute_callable
    return execute_callable(context=context, **execute_callable_kwargs)
           ^^^^^^^^^^^^^^^^^^^^^^^^^^^^^^^^^^^^^^^^^^^^^^^^^^^^^^^^^^^^
  File "/home/airflow/.local/lib/python3.12/site-packages/airflow/models/baseoperator.py", line 400, in wrapper
    return func(self, *args, **kwargs)
           ^^^^^^^^^^^^^^^^^^^^^^^^^^^
  File "/home/airflow/.local/lib/python3.12/site-packages/airflow/operators/python.py", line 235, in execute
    return_value = self.execute_callable()
                   ^^^^^^^^^^^^^^^^^^^^^^^
  File "/home/airflow/.local/lib/python3.12/site-packages/airflow/operators/python.py", line 252, in execute_callable
    return self.python_callable(*self.op_args, **self.op_kwargs)
           ^^^^^^^^^^^^^^^^^^^^^^^^^^^^^^^^^^^^^^^^^^^^^^^^^^^^^
  File "/opt/airflow/dags/pipe.py", line 124, in fetch_recent_data_to_csv
    df.to_csv(output_file, index=False)
    ^^
NameError: name 'df' is not defined
[2024-06-05T16:50:51.959+0000] {taskinstance.py:1206} INFO - Marking task as UP_FOR_RETRY. dag_id=s3_postgres, task_id=fetch_recent_data, run_id=manual__2024-06-05T16:35:59.651756+00:00, execution_date=20240605T163559, start_date=20240605T165051, end_date=20240605T165051
[2024-06-05T16:50:51.973+0000] {standard_task_runner.py:110} ERROR - Failed to execute job 724 for task fetch_recent_data (name 'df' is not defined; 73)
[2024-06-05T16:50:51.988+0000] {local_task_job_runner.py:240} INFO - Task exited with return code 1
[2024-06-05T16:50:52.011+0000] {taskinstance.py:3498} INFO - 0 downstream tasks scheduled from follow-on schedule check
[2024-06-05T16:50:52.014+0000] {local_task_job_runner.py:222} INFO - ::endgroup::
